2024-07-21T09:29:26 {"block_run_id": 11, "block_uuid": "load_model", "pipeline_run_id": 2, "pipeline_schedule_id": 1, "pipeline_uuid": "weather_xgbc_pipeline", "hostname": "3187cd1d20f3", "block_type": "data_loader", "level": "INFO", "message": "Start executing block with BlockExecutor.", "timestamp": 1721554166.03535, "uuid": "7e0854001b0e40cc93cf80810c75bcae"}
2024-07-21T09:29:27 {"block_run_id": 11, "block_uuid": "load_model", "pipeline_run_id": 2, "pipeline_schedule_id": 1, "pipeline_uuid": "weather_xgbc_pipeline", "hostname": "3187cd1d20f3", "block_type": "data_loader", "level": "INFO", "message": "", "timestamp": 1721554167.066231, "uuid": "70133a16986e4dcaa4def011db0b5809"}
2024-07-21T09:29:27 {"block_run_id": 11, "block_uuid": "load_model", "pipeline_run_id": 2, "pipeline_schedule_id": 1, "pipeline_uuid": "weather_xgbc_pipeline", "hostname": "3187cd1d20f3", "block_type": "data_loader", "level": "INFO", "message": "Downloading artifacts:   0%|          | 0/1 [00:00<?, ?it/s]", "timestamp": 1721554167.069356, "uuid": "52d4474efdd5444dae96c30c6f2484b4"}
2024-07-21T09:30:27 {"block_run_id": 11, "block_uuid": "load_model", "pipeline_run_id": 2, "pipeline_schedule_id": 1, "pipeline_uuid": "weather_xgbc_pipeline", "hostname": "3187cd1d20f3", "block_type": "data_loader", "level": "INFO", "message": "", "timestamp": 1721554227.128203, "uuid": "b7a2de0fa9a941f6937505b9c9da096d"}
2024-07-21T09:30:27 {"block_run_id": 11, "block_uuid": "load_model", "pipeline_run_id": 2, "pipeline_schedule_id": 1, "pipeline_uuid": "weather_xgbc_pipeline", "hostname": "3187cd1d20f3", "block_type": "data_loader", "level": "INFO", "message": "Downloading artifacts:   0%|          | 0/1 [01:00<?, ?it/s]", "timestamp": 1721554227.129232, "uuid": "64cc83ddc1cc4187ba8fe86073ca61d1"}
2024-07-21T09:30:27 {"block_run_id": 11, "block_uuid": "load_model", "pipeline_run_id": 2, "pipeline_schedule_id": 1, "pipeline_uuid": "weather_xgbc_pipeline", "hostname": "3187cd1d20f3", "block_type": "data_loader", "level": "WARNING", "message": "Exception thrown when attempting to run <function BlockExecutor.execute.<locals>.__execute_with_retry at 0x7fc36432db40>, attempt 1 of 1", "timestamp": 1721554227.185531, "uuid": "3c8fe197d9034416873319d2203cf5d8", "error": ["Traceback (most recent call last):\n  File \"/usr/local/lib/python3.10/site-packages/mage_ai/shared/retry.py\", line 38, in retry_func\n    return func(*args, **kwargs)\n  File \"/usr/local/lib/python3.10/site-packages/mage_ai/data_preparation/executors/block_executor.py\", line 621, in __execute_with_retry\n    return self._execute(\n  File \"/usr/local/lib/python3.10/site-packages/mage_ai/data_preparation/executors/block_executor.py\", line 1154, in _execute\n    result = self.block.execute_sync(\n  File \"/usr/local/lib/python3.10/site-packages/mage_ai/data_preparation/models/block/__init__.py\", line 1673, in execute_sync\n    return __execute()\n  File \"/usr/local/lib/python3.10/site-packages/mage_ai/data_preparation/models/block/__init__.py\", line 1650, in __execute\n    raise err\n  File \"/usr/local/lib/python3.10/site-packages/mage_ai/data_preparation/models/block/__init__.py\", line 1552, in __execute\n    output = self.execute_block(\n  File \"/usr/local/lib/python3.10/site-packages/mage_ai/data_preparation/models/block/__init__.py\", line 1892, in execute_block\n    outputs = self._execute_block(\n  File \"/usr/local/lib/python3.10/site-packages/mage_ai/data_preparation/models/block/__init__.py\", line 2055, in _execute_block\n    outputs = self.execute_block_function(\n  File \"/usr/local/lib/python3.10/site-packages/mage_ai/data_preparation/models/block/__init__.py\", line 2151, in execute_block_function\n    output = block_function_updated(*input_vars, **global_vars)\n  File \"<string>\", line 25, in load_data\n  File \"/usr/local/lib/python3.10/site-packages/mlflow/tracing/provider.py\", line 237, in wrapper\n    is_func_called, result = True, f(*args, **kwargs)\n  File \"/usr/local/lib/python3.10/site-packages/mlflow/pyfunc/__init__.py\", line 985, in load_model\n    local_path = _download_artifact_from_uri(\n  File \"/usr/local/lib/python3.10/site-packages/mlflow/tracking/artifact_utils.py\", line 111, in _download_artifact_from_uri\n    return repo.download_artifacts(\n  File \"/usr/local/lib/python3.10/site-packages/mlflow/store/artifact/models_artifact_repo.py\", line 190, in download_artifacts\n    model_path = self.repo.download_artifacts(artifact_path, dst_path)\n  File \"/usr/local/lib/python3.10/site-packages/mlflow/store/artifact/artifact_repo.py\", line 274, in download_artifacts\n    raise MlflowException(\nmlflow.exceptions.MlflowException: The following failures occurred while downloading one or more artifacts from http://mlflow:5000/api/2.0/mlflow-artifacts/artifacts/2/023a3dcd88d64d7e8810b25cfc2f5e0f/artifacts/model:\n##### File  #####\nAPI request to http://mlflow:5000/api/2.0/mlflow-artifacts/artifacts/2/023a3dcd88d64d7e8810b25cfc2f5e0f/artifacts/model/ failed with exception HTTPConnectionPool(host='mlflow', port=5000): Max retries exceeded with url: /api/2.0/mlflow-artifacts/artifacts/2/023a3dcd88d64d7e8810b25cfc2f5e0f/artifacts/model/ (Caused by ResponseError('too many 500 error responses'))\n"], "error_stack": [["  File \"/usr/local/bin/mage\", line 8, in <module>\n    sys.exit(app())\n", "  File \"/usr/local/lib/python3.10/site-packages/typer/main.py\", line 311, in __call__\n    return get_command(self)(*args, **kwargs)\n", "  File \"/usr/local/lib/python3.10/site-packages/click/core.py\", line 1130, in __call__\n    return self.main(*args, **kwargs)\n", "  File \"/usr/local/lib/python3.10/site-packages/typer/core.py\", line 778, in main\n    return _main(\n", "  File \"/usr/local/lib/python3.10/site-packages/typer/core.py\", line 216, in _main\n    rv = self.invoke(ctx)\n", "  File \"/usr/local/lib/python3.10/site-packages/click/core.py\", line 1657, in invoke\n    return _process_result(sub_ctx.command.invoke(sub_ctx))\n", "  File \"/usr/local/lib/python3.10/site-packages/click/core.py\", line 1404, in invoke\n    return ctx.invoke(self.callback, **ctx.params)\n", "  File \"/usr/local/lib/python3.10/site-packages/click/core.py\", line 760, in invoke\n    return __callback(*args, **kwargs)\n", "  File \"/usr/local/lib/python3.10/site-packages/typer/main.py\", line 683, in wrapper\n    return callback(**use_params)  # type: ignore\n", "  File \"/usr/local/lib/python3.10/site-packages/mage_ai/cli/main.py\", line 147, in start\n    start_server(\n", "  File \"/usr/local/lib/python3.10/site-packages/mage_ai/server/server.py\", line 787, in start_server\n    scheduler_manager.start_scheduler()\n", "  File \"/usr/local/lib/python3.10/site-packages/mage_ai/server/scheduler_manager.py\", line 106, in start_scheduler\n    proc.start()\n", "  File \"/usr/local/lib/python3.10/multiprocessing/process.py\", line 121, in start\n    self._popen = self._Popen(self)\n", "  File \"/usr/local/lib/python3.10/multiprocessing/context.py\", line 224, in _Popen\n    return _default_context.get_context().Process._Popen(process_obj)\n", "  File \"/usr/local/lib/python3.10/multiprocessing/context.py\", line 281, in _Popen\n    return Popen(process_obj)\n", "  File \"/usr/local/lib/python3.10/multiprocessing/popen_fork.py\", line 19, in __init__\n    self._launch(process_obj)\n", "  File \"/usr/local/lib/python3.10/multiprocessing/popen_fork.py\", line 71, in _launch\n    code = process_obj._bootstrap(parent_sentinel=child_r)\n", "  File \"/usr/local/lib/python3.10/multiprocessing/process.py\", line 314, in _bootstrap\n    self.run()\n", "  File \"/usr/local/lib/python3.10/multiprocessing/process.py\", line 108, in run\n    self._target(*self._args, **self._kwargs)\n", "  File \"/usr/local/lib/python3.10/site-packages/mage_ai/orchestration/db/process.py\", line 15, in start_session_and_run\n    results = target(*args)\n", "  File \"/usr/local/lib/python3.10/site-packages/mage_ai/server/scheduler_manager.py\", line 58, in run_scheduler\n    LoopTimeTrigger().start()\n", "  File \"/usr/local/lib/python3.10/site-packages/mage_ai/orchestration/triggers/loop_time_trigger.py\", line 14, in start\n    self.run()\n", "  File \"/usr/local/lib/python3.10/site-packages/mage_ai/orchestration/triggers/time_trigger.py\", line 11, in run\n    schedule_all()\n", "  File \"/usr/local/lib/python3.10/site-packages/mage_ai/orchestration/pipeline_scheduler_original.py\", line 1707, in schedule_all\n    PipelineScheduler(r).start()\n", "  File \"/usr/local/lib/python3.10/site-packages/mage_ai/orchestration/db/__init__.py\", line 158, in func_with_rollback\n    return func(*args, **kwargs)\n", "  File \"/usr/local/lib/python3.10/site-packages/mage_ai/orchestration/pipeline_scheduler_original.py\", line 198, in start\n    self.schedule()\n", "  File \"/usr/local/lib/python3.10/site-packages/mage_ai/orchestration/db/__init__.py\", line 158, in func_with_rollback\n    return func(*args, **kwargs)\n", "  File \"/usr/local/lib/python3.10/site-packages/mage_ai/orchestration/pipeline_scheduler_original.py\", line 334, in schedule\n    self.__schedule_blocks(block_runs)\n", "  File \"/usr/local/lib/python3.10/site-packages/mage_ai/orchestration/pipeline_scheduler_original.py\", line 641, in __schedule_blocks\n    job_manager.add_job(\n", "  File \"/usr/local/lib/python3.10/site-packages/mage_ai/orchestration/job_manager.py\", line 20, in add_job\n    self.queue.enqueue(job_id, target, *args, **kwargs)\n", "  File \"/usr/local/lib/python3.10/site-packages/mage_ai/orchestration/queue/process_queue.py\", line 121, in enqueue\n    self.start_worker_pool()\n", "  File \"/usr/local/lib/python3.10/site-packages/mage_ai/orchestration/queue/process_queue.py\", line 198, in start_worker_pool\n    self.worker_pool_proc.start()\n", "  File \"/usr/local/lib/python3.10/multiprocessing/process.py\", line 121, in start\n    self._popen = self._Popen(self)\n", "  File \"/usr/local/lib/python3.10/multiprocessing/context.py\", line 224, in _Popen\n    return _default_context.get_context().Process._Popen(process_obj)\n", "  File \"/usr/local/lib/python3.10/multiprocessing/context.py\", line 281, in _Popen\n    return Popen(process_obj)\n", "  File \"/usr/local/lib/python3.10/multiprocessing/popen_fork.py\", line 19, in __init__\n    self._launch(process_obj)\n", "  File \"/usr/local/lib/python3.10/multiprocessing/popen_fork.py\", line 71, in _launch\n    code = process_obj._bootstrap(parent_sentinel=child_r)\n", "  File \"/usr/local/lib/python3.10/multiprocessing/process.py\", line 314, in _bootstrap\n    self.run()\n", "  File \"/usr/local/lib/python3.10/multiprocessing/process.py\", line 108, in run\n    self._target(*self._args, **self._kwargs)\n", "  File \"/usr/local/lib/python3.10/site-packages/mage_ai/orchestration/queue/process_queue.py\", line 351, in poll_job_and_execute\n    worker.start()\n", "  File \"/usr/local/lib/python3.10/multiprocessing/process.py\", line 121, in start\n    self._popen = self._Popen(self)\n", "  File \"/usr/local/lib/python3.10/multiprocessing/context.py\", line 224, in _Popen\n    return _default_context.get_context().Process._Popen(process_obj)\n", "  File \"/usr/local/lib/python3.10/multiprocessing/context.py\", line 281, in _Popen\n    return Popen(process_obj)\n", "  File \"/usr/local/lib/python3.10/multiprocessing/popen_fork.py\", line 19, in __init__\n    self._launch(process_obj)\n", "  File \"/usr/local/lib/python3.10/multiprocessing/popen_fork.py\", line 71, in _launch\n    code = process_obj._bootstrap(parent_sentinel=child_r)\n", "  File \"/usr/local/lib/python3.10/multiprocessing/process.py\", line 314, in _bootstrap\n    self.run()\n", "  File \"/usr/local/lib/python3.10/site-packages/newrelic/api/background_task.py\", line 117, in wrapper\n    return wrapped(*args, **kwargs)\n", "  File \"/usr/local/lib/python3.10/site-packages/mage_ai/orchestration/queue/process_queue.py\", line 315, in run\n    start_session_and_run(args[1], *args[2], **args[3])\n", "  File \"/usr/local/lib/python3.10/site-packages/mage_ai/orchestration/db/process.py\", line 15, in start_session_and_run\n    results = target(*args)\n", "  File \"/usr/local/lib/python3.10/site-packages/mage_ai/orchestration/pipeline_scheduler_original.py\", line 1232, in run_block\n    return ExecutorFactory.get_block_executor(\n", "  File \"/usr/local/lib/python3.10/site-packages/mage_ai/data_preparation/executors/block_executor.py\", line 647, in execute\n    result = __execute_with_retry()\n", "  File \"/usr/local/lib/python3.10/site-packages/mage_ai/shared/retry.py\", line 46, in retry_func\n    logger.warning(\n", "  File \"/usr/local/lib/python3.10/site-packages/mage_ai/data_preparation/logging/logger.py\", line 39, in warning\n    self.__send_message('warning', message, **kwargs)\n", "  File \"/usr/local/lib/python3.10/site-packages/mage_ai/data_preparation/logging/logger.py\", line 65, in __send_message\n    data['error_stack'] = traceback.format_stack(),\n"]], "error_stacktrace": ["The following failures occurred while downloading one or more artifacts from http://mlflow:5000/api/2.0/mlflow-artifacts/artifacts/2/023a3dcd88d64d7e8810b25cfc2f5e0f/artifacts/model:\n##### File  #####\nAPI request to http://mlflow:5000/api/2.0/mlflow-artifacts/artifacts/2/023a3dcd88d64d7e8810b25cfc2f5e0f/artifacts/model/ failed with exception HTTPConnectionPool(host='mlflow', port=5000): Max retries exceeded with url: /api/2.0/mlflow-artifacts/artifacts/2/023a3dcd88d64d7e8810b25cfc2f5e0f/artifacts/model/ (Caused by ResponseError('too many 500 error responses'))"]}
2024-07-21T09:30:27 {"block_run_id": 11, "block_uuid": "load_model", "pipeline_run_id": 2, "pipeline_schedule_id": 1, "pipeline_uuid": "weather_xgbc_pipeline", "hostname": "3187cd1d20f3", "block_type": "data_loader", "level": "EXCEPTION", "message": "Failed to execute block load_model", "timestamp": 1721554227.190531, "uuid": "120634ee5590485992a3d79e97a9c8b6", "error": ["Traceback (most recent call last):\n  File \"/usr/local/lib/python3.10/site-packages/mage_ai/data_preparation/executors/block_executor.py\", line 647, in execute\n    result = __execute_with_retry()\n  File \"/usr/local/lib/python3.10/site-packages/mage_ai/shared/retry.py\", line 54, in retry_func\n    raise e\n  File \"/usr/local/lib/python3.10/site-packages/mage_ai/shared/retry.py\", line 38, in retry_func\n    return func(*args, **kwargs)\n  File \"/usr/local/lib/python3.10/site-packages/mage_ai/data_preparation/executors/block_executor.py\", line 621, in __execute_with_retry\n    return self._execute(\n  File \"/usr/local/lib/python3.10/site-packages/mage_ai/data_preparation/executors/block_executor.py\", line 1154, in _execute\n    result = self.block.execute_sync(\n  File \"/usr/local/lib/python3.10/site-packages/mage_ai/data_preparation/models/block/__init__.py\", line 1673, in execute_sync\n    return __execute()\n  File \"/usr/local/lib/python3.10/site-packages/mage_ai/data_preparation/models/block/__init__.py\", line 1650, in __execute\n    raise err\n  File \"/usr/local/lib/python3.10/site-packages/mage_ai/data_preparation/models/block/__init__.py\", line 1552, in __execute\n    output = self.execute_block(\n  File \"/usr/local/lib/python3.10/site-packages/mage_ai/data_preparation/models/block/__init__.py\", line 1892, in execute_block\n    outputs = self._execute_block(\n  File \"/usr/local/lib/python3.10/site-packages/mage_ai/data_preparation/models/block/__init__.py\", line 2055, in _execute_block\n    outputs = self.execute_block_function(\n  File \"/usr/local/lib/python3.10/site-packages/mage_ai/data_preparation/models/block/__init__.py\", line 2151, in execute_block_function\n    output = block_function_updated(*input_vars, **global_vars)\n  File \"<string>\", line 25, in load_data\n  File \"/usr/local/lib/python3.10/site-packages/mlflow/tracing/provider.py\", line 237, in wrapper\n    is_func_called, result = True, f(*args, **kwargs)\n  File \"/usr/local/lib/python3.10/site-packages/mlflow/pyfunc/__init__.py\", line 985, in load_model\n    local_path = _download_artifact_from_uri(\n  File \"/usr/local/lib/python3.10/site-packages/mlflow/tracking/artifact_utils.py\", line 111, in _download_artifact_from_uri\n    return repo.download_artifacts(\n  File \"/usr/local/lib/python3.10/site-packages/mlflow/store/artifact/models_artifact_repo.py\", line 190, in download_artifacts\n    model_path = self.repo.download_artifacts(artifact_path, dst_path)\n  File \"/usr/local/lib/python3.10/site-packages/mlflow/store/artifact/artifact_repo.py\", line 274, in download_artifacts\n    raise MlflowException(\nmlflow.exceptions.MlflowException: The following failures occurred while downloading one or more artifacts from http://mlflow:5000/api/2.0/mlflow-artifacts/artifacts/2/023a3dcd88d64d7e8810b25cfc2f5e0f/artifacts/model:\n##### File  #####\nAPI request to http://mlflow:5000/api/2.0/mlflow-artifacts/artifacts/2/023a3dcd88d64d7e8810b25cfc2f5e0f/artifacts/model/ failed with exception HTTPConnectionPool(host='mlflow', port=5000): Max retries exceeded with url: /api/2.0/mlflow-artifacts/artifacts/2/023a3dcd88d64d7e8810b25cfc2f5e0f/artifacts/model/ (Caused by ResponseError('too many 500 error responses'))\n"], "error_stack": [["  File \"/usr/local/bin/mage\", line 8, in <module>\n    sys.exit(app())\n", "  File \"/usr/local/lib/python3.10/site-packages/typer/main.py\", line 311, in __call__\n    return get_command(self)(*args, **kwargs)\n", "  File \"/usr/local/lib/python3.10/site-packages/click/core.py\", line 1130, in __call__\n    return self.main(*args, **kwargs)\n", "  File \"/usr/local/lib/python3.10/site-packages/typer/core.py\", line 778, in main\n    return _main(\n", "  File \"/usr/local/lib/python3.10/site-packages/typer/core.py\", line 216, in _main\n    rv = self.invoke(ctx)\n", "  File \"/usr/local/lib/python3.10/site-packages/click/core.py\", line 1657, in invoke\n    return _process_result(sub_ctx.command.invoke(sub_ctx))\n", "  File \"/usr/local/lib/python3.10/site-packages/click/core.py\", line 1404, in invoke\n    return ctx.invoke(self.callback, **ctx.params)\n", "  File \"/usr/local/lib/python3.10/site-packages/click/core.py\", line 760, in invoke\n    return __callback(*args, **kwargs)\n", "  File \"/usr/local/lib/python3.10/site-packages/typer/main.py\", line 683, in wrapper\n    return callback(**use_params)  # type: ignore\n", "  File \"/usr/local/lib/python3.10/site-packages/mage_ai/cli/main.py\", line 147, in start\n    start_server(\n", "  File \"/usr/local/lib/python3.10/site-packages/mage_ai/server/server.py\", line 787, in start_server\n    scheduler_manager.start_scheduler()\n", "  File \"/usr/local/lib/python3.10/site-packages/mage_ai/server/scheduler_manager.py\", line 106, in start_scheduler\n    proc.start()\n", "  File \"/usr/local/lib/python3.10/multiprocessing/process.py\", line 121, in start\n    self._popen = self._Popen(self)\n", "  File \"/usr/local/lib/python3.10/multiprocessing/context.py\", line 224, in _Popen\n    return _default_context.get_context().Process._Popen(process_obj)\n", "  File \"/usr/local/lib/python3.10/multiprocessing/context.py\", line 281, in _Popen\n    return Popen(process_obj)\n", "  File \"/usr/local/lib/python3.10/multiprocessing/popen_fork.py\", line 19, in __init__\n    self._launch(process_obj)\n", "  File \"/usr/local/lib/python3.10/multiprocessing/popen_fork.py\", line 71, in _launch\n    code = process_obj._bootstrap(parent_sentinel=child_r)\n", "  File \"/usr/local/lib/python3.10/multiprocessing/process.py\", line 314, in _bootstrap\n    self.run()\n", "  File \"/usr/local/lib/python3.10/multiprocessing/process.py\", line 108, in run\n    self._target(*self._args, **self._kwargs)\n", "  File \"/usr/local/lib/python3.10/site-packages/mage_ai/orchestration/db/process.py\", line 15, in start_session_and_run\n    results = target(*args)\n", "  File \"/usr/local/lib/python3.10/site-packages/mage_ai/server/scheduler_manager.py\", line 58, in run_scheduler\n    LoopTimeTrigger().start()\n", "  File \"/usr/local/lib/python3.10/site-packages/mage_ai/orchestration/triggers/loop_time_trigger.py\", line 14, in start\n    self.run()\n", "  File \"/usr/local/lib/python3.10/site-packages/mage_ai/orchestration/triggers/time_trigger.py\", line 11, in run\n    schedule_all()\n", "  File \"/usr/local/lib/python3.10/site-packages/mage_ai/orchestration/pipeline_scheduler_original.py\", line 1707, in schedule_all\n    PipelineScheduler(r).start()\n", "  File \"/usr/local/lib/python3.10/site-packages/mage_ai/orchestration/db/__init__.py\", line 158, in func_with_rollback\n    return func(*args, **kwargs)\n", "  File \"/usr/local/lib/python3.10/site-packages/mage_ai/orchestration/pipeline_scheduler_original.py\", line 198, in start\n    self.schedule()\n", "  File \"/usr/local/lib/python3.10/site-packages/mage_ai/orchestration/db/__init__.py\", line 158, in func_with_rollback\n    return func(*args, **kwargs)\n", "  File \"/usr/local/lib/python3.10/site-packages/mage_ai/orchestration/pipeline_scheduler_original.py\", line 334, in schedule\n    self.__schedule_blocks(block_runs)\n", "  File \"/usr/local/lib/python3.10/site-packages/mage_ai/orchestration/pipeline_scheduler_original.py\", line 641, in __schedule_blocks\n    job_manager.add_job(\n", "  File \"/usr/local/lib/python3.10/site-packages/mage_ai/orchestration/job_manager.py\", line 20, in add_job\n    self.queue.enqueue(job_id, target, *args, **kwargs)\n", "  File \"/usr/local/lib/python3.10/site-packages/mage_ai/orchestration/queue/process_queue.py\", line 121, in enqueue\n    self.start_worker_pool()\n", "  File \"/usr/local/lib/python3.10/site-packages/mage_ai/orchestration/queue/process_queue.py\", line 198, in start_worker_pool\n    self.worker_pool_proc.start()\n", "  File \"/usr/local/lib/python3.10/multiprocessing/process.py\", line 121, in start\n    self._popen = self._Popen(self)\n", "  File \"/usr/local/lib/python3.10/multiprocessing/context.py\", line 224, in _Popen\n    return _default_context.get_context().Process._Popen(process_obj)\n", "  File \"/usr/local/lib/python3.10/multiprocessing/context.py\", line 281, in _Popen\n    return Popen(process_obj)\n", "  File \"/usr/local/lib/python3.10/multiprocessing/popen_fork.py\", line 19, in __init__\n    self._launch(process_obj)\n", "  File \"/usr/local/lib/python3.10/multiprocessing/popen_fork.py\", line 71, in _launch\n    code = process_obj._bootstrap(parent_sentinel=child_r)\n", "  File \"/usr/local/lib/python3.10/multiprocessing/process.py\", line 314, in _bootstrap\n    self.run()\n", "  File \"/usr/local/lib/python3.10/multiprocessing/process.py\", line 108, in run\n    self._target(*self._args, **self._kwargs)\n", "  File \"/usr/local/lib/python3.10/site-packages/mage_ai/orchestration/queue/process_queue.py\", line 351, in poll_job_and_execute\n    worker.start()\n", "  File \"/usr/local/lib/python3.10/multiprocessing/process.py\", line 121, in start\n    self._popen = self._Popen(self)\n", "  File \"/usr/local/lib/python3.10/multiprocessing/context.py\", line 224, in _Popen\n    return _default_context.get_context().Process._Popen(process_obj)\n", "  File \"/usr/local/lib/python3.10/multiprocessing/context.py\", line 281, in _Popen\n    return Popen(process_obj)\n", "  File \"/usr/local/lib/python3.10/multiprocessing/popen_fork.py\", line 19, in __init__\n    self._launch(process_obj)\n", "  File \"/usr/local/lib/python3.10/multiprocessing/popen_fork.py\", line 71, in _launch\n    code = process_obj._bootstrap(parent_sentinel=child_r)\n", "  File \"/usr/local/lib/python3.10/multiprocessing/process.py\", line 314, in _bootstrap\n    self.run()\n", "  File \"/usr/local/lib/python3.10/site-packages/newrelic/api/background_task.py\", line 117, in wrapper\n    return wrapped(*args, **kwargs)\n", "  File \"/usr/local/lib/python3.10/site-packages/mage_ai/orchestration/queue/process_queue.py\", line 315, in run\n    start_session_and_run(args[1], *args[2], **args[3])\n", "  File \"/usr/local/lib/python3.10/site-packages/mage_ai/orchestration/db/process.py\", line 15, in start_session_and_run\n    results = target(*args)\n", "  File \"/usr/local/lib/python3.10/site-packages/mage_ai/orchestration/pipeline_scheduler_original.py\", line 1232, in run_block\n    return ExecutorFactory.get_block_executor(\n", "  File \"/usr/local/lib/python3.10/site-packages/mage_ai/data_preparation/executors/block_executor.py\", line 649, in execute\n    self.logger.exception(\n", "  File \"/usr/local/lib/python3.10/site-packages/mage_ai/data_preparation/logging/logger.py\", line 30, in exception\n    self.__send_message('exception', message, **kwargs)\n", "  File \"/usr/local/lib/python3.10/site-packages/mage_ai/data_preparation/logging/logger.py\", line 65, in __send_message\n    data['error_stack'] = traceback.format_stack(),\n"]], "error_stacktrace": ["The following failures occurred while downloading one or more artifacts from http://mlflow:5000/api/2.0/mlflow-artifacts/artifacts/2/023a3dcd88d64d7e8810b25cfc2f5e0f/artifacts/model:\n##### File  #####\nAPI request to http://mlflow:5000/api/2.0/mlflow-artifacts/artifacts/2/023a3dcd88d64d7e8810b25cfc2f5e0f/artifacts/model/ failed with exception HTTPConnectionPool(host='mlflow', port=5000): Max retries exceeded with url: /api/2.0/mlflow-artifacts/artifacts/2/023a3dcd88d64d7e8810b25cfc2f5e0f/artifacts/model/ (Caused by ResponseError('too many 500 error responses'))"]}
Traceback (most recent call last):
  File "/usr/local/lib/python3.10/site-packages/mage_ai/data_preparation/executors/block_executor.py", line 647, in execute
    result = __execute_with_retry()
  File "/usr/local/lib/python3.10/site-packages/mage_ai/shared/retry.py", line 54, in retry_func
    raise e
  File "/usr/local/lib/python3.10/site-packages/mage_ai/shared/retry.py", line 38, in retry_func
    return func(*args, **kwargs)
  File "/usr/local/lib/python3.10/site-packages/mage_ai/data_preparation/executors/block_executor.py", line 621, in __execute_with_retry
    return self._execute(
  File "/usr/local/lib/python3.10/site-packages/mage_ai/data_preparation/executors/block_executor.py", line 1154, in _execute
    result = self.block.execute_sync(
  File "/usr/local/lib/python3.10/site-packages/mage_ai/data_preparation/models/block/__init__.py", line 1673, in execute_sync
    return __execute()
  File "/usr/local/lib/python3.10/site-packages/mage_ai/data_preparation/models/block/__init__.py", line 1650, in __execute
    raise err
  File "/usr/local/lib/python3.10/site-packages/mage_ai/data_preparation/models/block/__init__.py", line 1552, in __execute
    output = self.execute_block(
  File "/usr/local/lib/python3.10/site-packages/mage_ai/data_preparation/models/block/__init__.py", line 1892, in execute_block
    outputs = self._execute_block(
  File "/usr/local/lib/python3.10/site-packages/mage_ai/data_preparation/models/block/__init__.py", line 2055, in _execute_block
    outputs = self.execute_block_function(
  File "/usr/local/lib/python3.10/site-packages/mage_ai/data_preparation/models/block/__init__.py", line 2151, in execute_block_function
    output = block_function_updated(*input_vars, **global_vars)
  File "<string>", line 25, in load_data
  File "/usr/local/lib/python3.10/site-packages/mlflow/tracing/provider.py", line 237, in wrapper
    is_func_called, result = True, f(*args, **kwargs)
  File "/usr/local/lib/python3.10/site-packages/mlflow/pyfunc/__init__.py", line 985, in load_model
    local_path = _download_artifact_from_uri(
  File "/usr/local/lib/python3.10/site-packages/mlflow/tracking/artifact_utils.py", line 111, in _download_artifact_from_uri
    return repo.download_artifacts(
  File "/usr/local/lib/python3.10/site-packages/mlflow/store/artifact/models_artifact_repo.py", line 190, in download_artifacts
    model_path = self.repo.download_artifacts(artifact_path, dst_path)
  File "/usr/local/lib/python3.10/site-packages/mlflow/store/artifact/artifact_repo.py", line 274, in download_artifacts
    raise MlflowException(
mlflow.exceptions.MlflowException: The following failures occurred while downloading one or more artifacts from http://mlflow:5000/api/2.0/mlflow-artifacts/artifacts/2/023a3dcd88d64d7e8810b25cfc2f5e0f/artifacts/model:
##### File  #####
API request to http://mlflow:5000/api/2.0/mlflow-artifacts/artifacts/2/023a3dcd88d64d7e8810b25cfc2f5e0f/artifacts/model/ failed with exception HTTPConnectionPool(host='mlflow', port=5000): Max retries exceeded with url: /api/2.0/mlflow-artifacts/artifacts/2/023a3dcd88d64d7e8810b25cfc2f5e0f/artifacts/model/ (Caused by ResponseError('too many 500 error responses'))
