2024-07-21T09:29:24 {"cpu": 0.0703125, "cpu_total": 12, "cpu_usage": 0.005859375, "memory": 2735.0, "memory_total": 19967.0, "memory_usage": 0.13697601041718835, "pipeline_run_id": 2, "pipeline_schedule_id": 1, "pipeline_uuid": "weather_xgbc_pipeline", "hostname": "3187cd1d20f3", "level": "INFO", "message": "Pipeline weather_xgbc_pipeline for run 2 in schedule 1 is alive.", "timestamp": 1721554164.841346, "uuid": "3ac6e31878834bfd9e939c6d1ab7bc2b"}
2024-07-21T09:29:25 {"cpu": 0.0703125, "cpu_total": 12, "cpu_usage": 0.005859375, "memory": 2767.0, "memory_total": 19967.0, "memory_usage": 0.13857865478038764, "pipeline_run_id": 2, "pipeline_schedule_id": 1, "pipeline_uuid": "weather_xgbc_pipeline", "hostname": "3187cd1d20f3", "level": "INFO", "message": "Pipeline weather_xgbc_pipeline for run 2 in schedule 1 is alive.", "timestamp": 1721554165.013467, "uuid": "0a4106aca42a4f82805e5a31fca72c88"}
2024-07-21T09:29:25 {"block_run_id": 6, "block_uuid": "load", "pipeline_run_id": 2, "pipeline_schedule_id": 1, "pipeline_uuid": "weather_xgbc_pipeline", "hostname": "3187cd1d20f3", "level": "INFO", "message": "Execute PipelineRun 2, BlockRun 6: pipeline weather_xgbc_pipeline block load", "timestamp": 1721554165.015358, "uuid": "9c9826219aeb4c9681fa893206fafb08"}
2024-07-21T09:29:25 {"block_run_id": 6, "block_uuid": "load", "pipeline_run_id": 2, "pipeline_schedule_id": 1, "pipeline_uuid": "weather_xgbc_pipeline", "hostname": "3187cd1d20f3", "level": "INFO", "message": "BlockRun 6 (block_uuid: load) completes.", "timestamp": 1721554165.325822, "uuid": "e3737a2a703342d2ad95ef48eeae8f81"}
2024-07-21T09:29:26 {"block_run_id": 11, "block_uuid": "load_model", "pipeline_run_id": 2, "pipeline_schedule_id": 1, "pipeline_uuid": "weather_xgbc_pipeline", "hostname": "3187cd1d20f3", "level": "INFO", "message": "Execute PipelineRun 2, BlockRun 11: pipeline weather_xgbc_pipeline block load_model", "timestamp": 1721554166.015281, "uuid": "14223dbe48bb434aa65605fa6d0e4c7c"}
2024-07-21T09:29:34 {"cpu": 0.0751953125, "cpu_total": 12, "cpu_usage": 0.006266276041666667, "memory": 2914.0, "memory_total": 19967.0, "memory_usage": 0.14594080232383433, "pipeline_run_id": 2, "pipeline_schedule_id": 1, "pipeline_uuid": "weather_xgbc_pipeline", "hostname": "3187cd1d20f3", "level": "INFO", "message": "Pipeline weather_xgbc_pipeline for run 2 in schedule 1 is alive.", "timestamp": 1721554174.16945, "uuid": "d1c758de3c4c461d9c39f8dbd2a6b784"}
2024-07-21T09:29:35 {"block_run_id": 7, "block_uuid": "transform", "pipeline_run_id": 2, "pipeline_schedule_id": 1, "pipeline_uuid": "weather_xgbc_pipeline", "hostname": "3187cd1d20f3", "level": "INFO", "message": "Execute PipelineRun 2, BlockRun 7: pipeline weather_xgbc_pipeline block transform", "timestamp": 1721554175.056243, "uuid": "8d678cebbe8c4d96aac75167a2cefae5"}
2024-07-21T09:29:35 {"block_run_id": 7, "block_uuid": "transform", "pipeline_run_id": 2, "pipeline_schedule_id": 1, "pipeline_uuid": "weather_xgbc_pipeline", "hostname": "3187cd1d20f3", "level": "INFO", "message": "BlockRun 7 (block_uuid: transform) completes.", "timestamp": 1721554175.495935, "uuid": "fe757393552a4e05baab6ce055ef47b3"}
2024-07-21T09:29:44 {"cpu": 0.07421875, "cpu_total": 12, "cpu_usage": 0.006184895833333333, "memory": 2914.0, "memory_total": 19967.0, "memory_usage": 0.14594080232383433, "pipeline_run_id": 2, "pipeline_schedule_id": 1, "pipeline_uuid": "weather_xgbc_pipeline", "hostname": "3187cd1d20f3", "level": "INFO", "message": "Pipeline weather_xgbc_pipeline for run 2 in schedule 1 is alive.", "timestamp": 1721554184.366497, "uuid": "52aa953ebf764c62a0b92f8708bcfabf"}
2024-07-21T09:29:45 {"block_run_id": 8, "block_uuid": "train", "pipeline_run_id": 2, "pipeline_schedule_id": 1, "pipeline_uuid": "weather_xgbc_pipeline", "hostname": "3187cd1d20f3", "level": "INFO", "message": "Execute PipelineRun 2, BlockRun 8: pipeline weather_xgbc_pipeline block train", "timestamp": 1721554185.077689, "uuid": "2c5379e4b8374ceaab23d0feb470a1e5"}
2024-07-21T09:29:46 {"block_run_id": 8, "block_uuid": "train", "pipeline_run_id": 2, "pipeline_schedule_id": 1, "pipeline_uuid": "weather_xgbc_pipeline", "hostname": "3187cd1d20f3", "level": "INFO", "message": "BlockRun 8 (block_uuid: train) completes.", "timestamp": 1721554186.61183, "uuid": "859bd00535c747429e4aecfa31693a31"}
2024-07-21T09:29:54 {"cpu": 0.0732421875, "cpu_total": 12, "cpu_usage": 0.006103515625, "memory": 2913.0, "memory_total": 19967.0, "memory_usage": 0.14589071968748435, "pipeline_run_id": 2, "pipeline_schedule_id": 1, "pipeline_uuid": "weather_xgbc_pipeline", "hostname": "3187cd1d20f3", "level": "INFO", "message": "Pipeline weather_xgbc_pipeline for run 2 in schedule 1 is alive.", "timestamp": 1721554194.56296, "uuid": "dae697b74fb5400eacf6802b730380d6"}
2024-07-21T09:29:55 {"block_run_id": 9, "block_uuid": "save", "pipeline_run_id": 2, "pipeline_schedule_id": 1, "pipeline_uuid": "weather_xgbc_pipeline", "hostname": "3187cd1d20f3", "level": "INFO", "message": "Execute PipelineRun 2, BlockRun 9: pipeline weather_xgbc_pipeline block save", "timestamp": 1721554195.104725, "uuid": "dc3226c0b28444578a2b2e1f4b4cd4c2"}
2024-07-21T09:30:04 {"cpu": 0.1484375, "cpu_total": 12, "cpu_usage": 0.012369791666666666, "memory": 3164.0, "memory_total": 19967.0, "memory_usage": 0.1584614614113287, "pipeline_run_id": 2, "pipeline_schedule_id": 1, "pipeline_uuid": "weather_xgbc_pipeline", "hostname": "3187cd1d20f3", "level": "INFO", "message": "Pipeline weather_xgbc_pipeline for run 2 in schedule 1 is alive.", "timestamp": 1721554204.788038, "uuid": "437e408344174a6cae35ecb146988bc5"}
2024-07-21T09:30:14 {"cpu": 0.2705078125, "cpu_total": 12, "cpu_usage": 0.022542317708333332, "memory": 3175.0, "memory_total": 19967.0, "memory_usage": 0.15901237041117844, "pipeline_run_id": 2, "pipeline_schedule_id": 1, "pipeline_uuid": "weather_xgbc_pipeline", "hostname": "3187cd1d20f3", "level": "INFO", "message": "Pipeline weather_xgbc_pipeline for run 2 in schedule 1 is alive.", "timestamp": 1721554214.986991, "uuid": "35e466e8ac5347dfb03647bc963c2519"}
2024-07-21T09:30:24 {"cpu": 0.39697265625, "cpu_total": 12, "cpu_usage": 0.0330810546875, "memory": 3206.0, "memory_total": 19967.0, "memory_usage": 0.16056493213802775, "pipeline_run_id": 2, "pipeline_schedule_id": 1, "pipeline_uuid": "weather_xgbc_pipeline", "hostname": "3187cd1d20f3", "level": "INFO", "message": "Pipeline weather_xgbc_pipeline for run 2 in schedule 1 is alive.", "timestamp": 1721554224.197776, "uuid": "72fec9f3fe7d41db85f791c090c4ce6e"}
2024-07-21T09:30:28 {"block_run_id": 11, "block_uuid": "load_model", "pipeline_run_id": 2, "pipeline_schedule_id": 1, "pipeline_uuid": "weather_xgbc_pipeline", "hostname": "3187cd1d20f3", "level": "EXCEPTION", "message": "BlockRun 11 (block_uuid: load_model) failed.", "timestamp": 1721554228.280566, "uuid": "a066082edf034d9aa1f17edafe21de2c", "error": ["Traceback (most recent call last):\n  File \"/usr/local/lib/python3.10/site-packages/mage_ai/data_preparation/executors/block_executor.py\", line 647, in execute\n    result = __execute_with_retry()\n  File \"/usr/local/lib/python3.10/site-packages/mage_ai/shared/retry.py\", line 54, in retry_func\n    raise e\n  File \"/usr/local/lib/python3.10/site-packages/mage_ai/shared/retry.py\", line 38, in retry_func\n    return func(*args, **kwargs)\n  File \"/usr/local/lib/python3.10/site-packages/mage_ai/data_preparation/executors/block_executor.py\", line 621, in __execute_with_retry\n    return self._execute(\n  File \"/usr/local/lib/python3.10/site-packages/mage_ai/data_preparation/executors/block_executor.py\", line 1154, in _execute\n    result = self.block.execute_sync(\n  File \"/usr/local/lib/python3.10/site-packages/mage_ai/data_preparation/models/block/__init__.py\", line 1673, in execute_sync\n    return __execute()\n  File \"/usr/local/lib/python3.10/site-packages/mage_ai/data_preparation/models/block/__init__.py\", line 1650, in __execute\n    raise err\n  File \"/usr/local/lib/python3.10/site-packages/mage_ai/data_preparation/models/block/__init__.py\", line 1552, in __execute\n    output = self.execute_block(\n  File \"/usr/local/lib/python3.10/site-packages/mage_ai/data_preparation/models/block/__init__.py\", line 1892, in execute_block\n    outputs = self._execute_block(\n  File \"/usr/local/lib/python3.10/site-packages/mage_ai/data_preparation/models/block/__init__.py\", line 2055, in _execute_block\n    outputs = self.execute_block_function(\n  File \"/usr/local/lib/python3.10/site-packages/mage_ai/data_preparation/models/block/__init__.py\", line 2151, in execute_block_function\n    output = block_function_updated(*input_vars, **global_vars)\n  File \"<string>\", line 25, in load_data\n  File \"/usr/local/lib/python3.10/site-packages/mlflow/tracing/provider.py\", line 237, in wrapper\n    is_func_called, result = True, f(*args, **kwargs)\n  File \"/usr/local/lib/python3.10/site-packages/mlflow/pyfunc/__init__.py\", line 985, in load_model\n    local_path = _download_artifact_from_uri(\n  File \"/usr/local/lib/python3.10/site-packages/mlflow/tracking/artifact_utils.py\", line 111, in _download_artifact_from_uri\n    return repo.download_artifacts(\n  File \"/usr/local/lib/python3.10/site-packages/mlflow/store/artifact/models_artifact_repo.py\", line 190, in download_artifacts\n    model_path = self.repo.download_artifacts(artifact_path, dst_path)\n  File \"/usr/local/lib/python3.10/site-packages/mlflow/store/artifact/artifact_repo.py\", line 274, in download_artifacts\n    raise MlflowException(\nmlflow.exceptions.MlflowException: The following failures occurred while downloading one or more artifacts from http://mlflow:5000/api/2.0/mlflow-artifacts/artifacts/2/023a3dcd88d64d7e8810b25cfc2f5e0f/artifacts/model:\n##### File  #####\nAPI request to http://mlflow:5000/api/2.0/mlflow-artifacts/artifacts/2/023a3dcd88d64d7e8810b25cfc2f5e0f/artifacts/model/ failed with exception HTTPConnectionPool(host='mlflow', port=5000): Max retries exceeded with url: /api/2.0/mlflow-artifacts/artifacts/2/023a3dcd88d64d7e8810b25cfc2f5e0f/artifacts/model/ (Caused by ResponseError('too many 500 error responses'))\n"], "error_stack": [["  File \"/usr/local/bin/mage\", line 8, in <module>\n    sys.exit(app())\n", "  File \"/usr/local/lib/python3.10/site-packages/typer/main.py\", line 311, in __call__\n    return get_command(self)(*args, **kwargs)\n", "  File \"/usr/local/lib/python3.10/site-packages/click/core.py\", line 1130, in __call__\n    return self.main(*args, **kwargs)\n", "  File \"/usr/local/lib/python3.10/site-packages/typer/core.py\", line 778, in main\n    return _main(\n", "  File \"/usr/local/lib/python3.10/site-packages/typer/core.py\", line 216, in _main\n    rv = self.invoke(ctx)\n", "  File \"/usr/local/lib/python3.10/site-packages/click/core.py\", line 1657, in invoke\n    return _process_result(sub_ctx.command.invoke(sub_ctx))\n", "  File \"/usr/local/lib/python3.10/site-packages/click/core.py\", line 1404, in invoke\n    return ctx.invoke(self.callback, **ctx.params)\n", "  File \"/usr/local/lib/python3.10/site-packages/click/core.py\", line 760, in invoke\n    return __callback(*args, **kwargs)\n", "  File \"/usr/local/lib/python3.10/site-packages/typer/main.py\", line 683, in wrapper\n    return callback(**use_params)  # type: ignore\n", "  File \"/usr/local/lib/python3.10/site-packages/mage_ai/cli/main.py\", line 147, in start\n    start_server(\n", "  File \"/usr/local/lib/python3.10/site-packages/mage_ai/server/server.py\", line 787, in start_server\n    scheduler_manager.start_scheduler()\n", "  File \"/usr/local/lib/python3.10/site-packages/mage_ai/server/scheduler_manager.py\", line 106, in start_scheduler\n    proc.start()\n", "  File \"/usr/local/lib/python3.10/multiprocessing/process.py\", line 121, in start\n    self._popen = self._Popen(self)\n", "  File \"/usr/local/lib/python3.10/multiprocessing/context.py\", line 224, in _Popen\n    return _default_context.get_context().Process._Popen(process_obj)\n", "  File \"/usr/local/lib/python3.10/multiprocessing/context.py\", line 281, in _Popen\n    return Popen(process_obj)\n", "  File \"/usr/local/lib/python3.10/multiprocessing/popen_fork.py\", line 19, in __init__\n    self._launch(process_obj)\n", "  File \"/usr/local/lib/python3.10/multiprocessing/popen_fork.py\", line 71, in _launch\n    code = process_obj._bootstrap(parent_sentinel=child_r)\n", "  File \"/usr/local/lib/python3.10/multiprocessing/process.py\", line 314, in _bootstrap\n    self.run()\n", "  File \"/usr/local/lib/python3.10/multiprocessing/process.py\", line 108, in run\n    self._target(*self._args, **self._kwargs)\n", "  File \"/usr/local/lib/python3.10/site-packages/mage_ai/orchestration/db/process.py\", line 15, in start_session_and_run\n    results = target(*args)\n", "  File \"/usr/local/lib/python3.10/site-packages/mage_ai/server/scheduler_manager.py\", line 58, in run_scheduler\n    LoopTimeTrigger().start()\n", "  File \"/usr/local/lib/python3.10/site-packages/mage_ai/orchestration/triggers/loop_time_trigger.py\", line 14, in start\n    self.run()\n", "  File \"/usr/local/lib/python3.10/site-packages/mage_ai/orchestration/triggers/time_trigger.py\", line 11, in run\n    schedule_all()\n", "  File \"/usr/local/lib/python3.10/site-packages/mage_ai/orchestration/pipeline_scheduler_original.py\", line 1707, in schedule_all\n    PipelineScheduler(r).start()\n", "  File \"/usr/local/lib/python3.10/site-packages/mage_ai/orchestration/db/__init__.py\", line 158, in func_with_rollback\n    return func(*args, **kwargs)\n", "  File \"/usr/local/lib/python3.10/site-packages/mage_ai/orchestration/pipeline_scheduler_original.py\", line 198, in start\n    self.schedule()\n", "  File \"/usr/local/lib/python3.10/site-packages/mage_ai/orchestration/db/__init__.py\", line 158, in func_with_rollback\n    return func(*args, **kwargs)\n", "  File \"/usr/local/lib/python3.10/site-packages/mage_ai/orchestration/pipeline_scheduler_original.py\", line 334, in schedule\n    self.__schedule_blocks(block_runs)\n", "  File \"/usr/local/lib/python3.10/site-packages/mage_ai/orchestration/pipeline_scheduler_original.py\", line 641, in __schedule_blocks\n    job_manager.add_job(\n", "  File \"/usr/local/lib/python3.10/site-packages/mage_ai/orchestration/job_manager.py\", line 20, in add_job\n    self.queue.enqueue(job_id, target, *args, **kwargs)\n", "  File \"/usr/local/lib/python3.10/site-packages/mage_ai/orchestration/queue/process_queue.py\", line 121, in enqueue\n    self.start_worker_pool()\n", "  File \"/usr/local/lib/python3.10/site-packages/mage_ai/orchestration/queue/process_queue.py\", line 198, in start_worker_pool\n    self.worker_pool_proc.start()\n", "  File \"/usr/local/lib/python3.10/multiprocessing/process.py\", line 121, in start\n    self._popen = self._Popen(self)\n", "  File \"/usr/local/lib/python3.10/multiprocessing/context.py\", line 224, in _Popen\n    return _default_context.get_context().Process._Popen(process_obj)\n", "  File \"/usr/local/lib/python3.10/multiprocessing/context.py\", line 281, in _Popen\n    return Popen(process_obj)\n", "  File \"/usr/local/lib/python3.10/multiprocessing/popen_fork.py\", line 19, in __init__\n    self._launch(process_obj)\n", "  File \"/usr/local/lib/python3.10/multiprocessing/popen_fork.py\", line 71, in _launch\n    code = process_obj._bootstrap(parent_sentinel=child_r)\n", "  File \"/usr/local/lib/python3.10/multiprocessing/process.py\", line 314, in _bootstrap\n    self.run()\n", "  File \"/usr/local/lib/python3.10/multiprocessing/process.py\", line 108, in run\n    self._target(*self._args, **self._kwargs)\n", "  File \"/usr/local/lib/python3.10/site-packages/mage_ai/orchestration/queue/process_queue.py\", line 351, in poll_job_and_execute\n    worker.start()\n", "  File \"/usr/local/lib/python3.10/multiprocessing/process.py\", line 121, in start\n    self._popen = self._Popen(self)\n", "  File \"/usr/local/lib/python3.10/multiprocessing/context.py\", line 224, in _Popen\n    return _default_context.get_context().Process._Popen(process_obj)\n", "  File \"/usr/local/lib/python3.10/multiprocessing/context.py\", line 281, in _Popen\n    return Popen(process_obj)\n", "  File \"/usr/local/lib/python3.10/multiprocessing/popen_fork.py\", line 19, in __init__\n    self._launch(process_obj)\n", "  File \"/usr/local/lib/python3.10/multiprocessing/popen_fork.py\", line 71, in _launch\n    code = process_obj._bootstrap(parent_sentinel=child_r)\n", "  File \"/usr/local/lib/python3.10/multiprocessing/process.py\", line 314, in _bootstrap\n    self.run()\n", "  File \"/usr/local/lib/python3.10/site-packages/newrelic/api/background_task.py\", line 117, in wrapper\n    return wrapped(*args, **kwargs)\n", "  File \"/usr/local/lib/python3.10/site-packages/mage_ai/orchestration/queue/process_queue.py\", line 315, in run\n    start_session_and_run(args[1], *args[2], **args[3])\n", "  File \"/usr/local/lib/python3.10/site-packages/mage_ai/orchestration/db/process.py\", line 15, in start_session_and_run\n    results = target(*args)\n", "  File \"/usr/local/lib/python3.10/site-packages/mage_ai/orchestration/pipeline_scheduler_original.py\", line 1232, in run_block\n    return ExecutorFactory.get_block_executor(\n", "  File \"/usr/local/lib/python3.10/site-packages/mage_ai/data_preparation/executors/block_executor.py\", line 682, in execute\n    on_failure(\n", "  File \"/usr/local/lib/python3.10/site-packages/mage_ai/orchestration/db/__init__.py\", line 158, in func_with_rollback\n    return func(*args, **kwargs)\n", "  File \"/usr/local/lib/python3.10/site-packages/mage_ai/orchestration/pipeline_scheduler_original.py\", line 465, in on_block_failure\n    self.logger.exception(\n", "  File \"/usr/local/lib/python3.10/site-packages/mage_ai/data_preparation/logging/logger.py\", line 30, in exception\n    self.__send_message('exception', message, **kwargs)\n", "  File \"/usr/local/lib/python3.10/site-packages/mage_ai/data_preparation/logging/logger.py\", line 65, in __send_message\n    data['error_stack'] = traceback.format_stack(),\n"]], "error_stacktrace": ["The following failures occurred while downloading one or more artifacts from http://mlflow:5000/api/2.0/mlflow-artifacts/artifacts/2/023a3dcd88d64d7e8810b25cfc2f5e0f/artifacts/model:\n##### File  #####\nAPI request to http://mlflow:5000/api/2.0/mlflow-artifacts/artifacts/2/023a3dcd88d64d7e8810b25cfc2f5e0f/artifacts/model/ failed with exception HTTPConnectionPool(host='mlflow', port=5000): Max retries exceeded with url: /api/2.0/mlflow-artifacts/artifacts/2/023a3dcd88d64d7e8810b25cfc2f5e0f/artifacts/model/ (Caused by ResponseError('too many 500 error responses'))"]}
Traceback (most recent call last):
  File "/usr/local/lib/python3.10/site-packages/mage_ai/data_preparation/executors/block_executor.py", line 647, in execute
    result = __execute_with_retry()
  File "/usr/local/lib/python3.10/site-packages/mage_ai/shared/retry.py", line 54, in retry_func
    raise e
  File "/usr/local/lib/python3.10/site-packages/mage_ai/shared/retry.py", line 38, in retry_func
    return func(*args, **kwargs)
  File "/usr/local/lib/python3.10/site-packages/mage_ai/data_preparation/executors/block_executor.py", line 621, in __execute_with_retry
    return self._execute(
  File "/usr/local/lib/python3.10/site-packages/mage_ai/data_preparation/executors/block_executor.py", line 1154, in _execute
    result = self.block.execute_sync(
  File "/usr/local/lib/python3.10/site-packages/mage_ai/data_preparation/models/block/__init__.py", line 1673, in execute_sync
    return __execute()
  File "/usr/local/lib/python3.10/site-packages/mage_ai/data_preparation/models/block/__init__.py", line 1650, in __execute
    raise err
  File "/usr/local/lib/python3.10/site-packages/mage_ai/data_preparation/models/block/__init__.py", line 1552, in __execute
    output = self.execute_block(
  File "/usr/local/lib/python3.10/site-packages/mage_ai/data_preparation/models/block/__init__.py", line 1892, in execute_block
    outputs = self._execute_block(
  File "/usr/local/lib/python3.10/site-packages/mage_ai/data_preparation/models/block/__init__.py", line 2055, in _execute_block
    outputs = self.execute_block_function(
  File "/usr/local/lib/python3.10/site-packages/mage_ai/data_preparation/models/block/__init__.py", line 2151, in execute_block_function
    output = block_function_updated(*input_vars, **global_vars)
  File "<string>", line 25, in load_data
  File "/usr/local/lib/python3.10/site-packages/mlflow/tracing/provider.py", line 237, in wrapper
    is_func_called, result = True, f(*args, **kwargs)
  File "/usr/local/lib/python3.10/site-packages/mlflow/pyfunc/__init__.py", line 985, in load_model
    local_path = _download_artifact_from_uri(
  File "/usr/local/lib/python3.10/site-packages/mlflow/tracking/artifact_utils.py", line 111, in _download_artifact_from_uri
    return repo.download_artifacts(
  File "/usr/local/lib/python3.10/site-packages/mlflow/store/artifact/models_artifact_repo.py", line 190, in download_artifacts
    model_path = self.repo.download_artifacts(artifact_path, dst_path)
  File "/usr/local/lib/python3.10/site-packages/mlflow/store/artifact/artifact_repo.py", line 274, in download_artifacts
    raise MlflowException(
mlflow.exceptions.MlflowException: The following failures occurred while downloading one or more artifacts from http://mlflow:5000/api/2.0/mlflow-artifacts/artifacts/2/023a3dcd88d64d7e8810b25cfc2f5e0f/artifacts/model:
##### File  #####
API request to http://mlflow:5000/api/2.0/mlflow-artifacts/artifacts/2/023a3dcd88d64d7e8810b25cfc2f5e0f/artifacts/model/ failed with exception HTTPConnectionPool(host='mlflow', port=5000): Max retries exceeded with url: /api/2.0/mlflow-artifacts/artifacts/2/023a3dcd88d64d7e8810b25cfc2f5e0f/artifacts/model/ (Caused by ResponseError('too many 500 error responses'))
2024-07-21T09:30:34 {"cpu": 0.51611328125, "cpu_total": 12, "cpu_usage": 0.043009440104166664, "memory": 3072.0, "memory_total": 19967.0, "memory_usage": 0.15385385886713077, "pipeline_run_id": 2, "pipeline_schedule_id": 1, "pipeline_uuid": "weather_xgbc_pipeline", "hostname": "3187cd1d20f3", "level": "INFO", "message": "Pipeline weather_xgbc_pipeline for run 2 in schedule 1 is alive.", "timestamp": 1721554234.388428, "uuid": "b00e54dcea3d49c5b77df3049d5ad0fe"}
